Workbook

Sheet Theory & Parameters
A1: Quantum Harmonic Oscillator — Exact Mehler Kernel (Path-Integral Propagator)
A2: x_i = 0, x_f = 0→10 (step 0.25), T = 1, m = 1, ω = 1, ℏ = 1 (natural units)
A4: ▶ The Mehler Kernel — Exact QHO Propagator
A5: Harmonic Potential V(x) | C5: V(x) = ½·m·ω²·x² → with m = ω = 1 : V(x) = ½ x²
A6: Full Mehler Kernel (general x_i, x_f) | C6: K(x_f, T ; x_i, 0) = √[ mω / (2πiℏ sin(ωT)) ] × exp{ i·mω·[(x_i² + x_f²)·cos(ωT) − 2·x_i·x_f] / [2ℏ·sin(ωT)] }
A7: Simplified form x_i = 0 (our case) | C7: K(x_f, T ; 0, 0) = √[ mω / (2πiℏ·sin(ωT)) ] × exp{ i·mω·cos(ωT)·x_f² / [2ℏ·sin(ωT)] }
A8: Compact form A = prefactor, φ = phase coeff | C8: K = A · exp(i·φ·x_f²) where: A = √[mω/(2πiℏ·sinωT)] , φ = mω·cot(ωT) / (2ℏ)
A9: Prefactor breakdown |A| and θ_A | C9: |A| = √[ mω / (2πℏ·|sinωT|) ] θ_A = arg(A) = −π/4 (since A = √(pure-negative-imaginary) ⟹ arg = −π/4)
A10: Re and Im parts of K | C10: Re[K] = |A|·cos(θ_A + φ·x_f²) Im[K] = |A|·sin(θ_A + φ·x_f²)
A11: Modulus |K| (constant!) | C11: |K(x_f, T; 0, 0)| = |A| = √[ mω / (2πℏ·|sinωT|) ] ← independent of x_f (equal probability amplitude everywhere)
A12: Classical action / phase (x_i = 0) | C12: S_cl/ℏ = mω·cot(ωT)·x_f² / (2ℏ) → with m=ω=ℏ=1, T=1: S_cl/ℏ = cot(1)/2 · x_f²
A14: ▶ Input Parameters (yellow = user-editable inputs)
A15: Symbol | B15: Parameter Name | C15: Value | D15: Unit | E15: Notes
A16: m | B16: Particle mass | C16: 1 | D16: nat. units | E16: Mass of particle
A17: ω | B17: Angular frequency | C17: 1 | D17: rad/s | E17: Oscillator frequency
A18: T | B18: Propagation time | C18: 1 | D18: s | E18: Total time elapsed
A19: ℏ | B19: Reduced Planck constant | C19: 1 | D19: J·s | E19: Natural units: ℏ=1
A20: x_i | B20: Start position | C20: 0 | D20: — | E20: Fixed at origin
A21: ▶ Derived Values (formula cells — auto-update if parameters change)
A22: Symbol | B22: Expression | C22: Formula Cell | D22: Numeric Result | E22: Notes
A23: sin(ωT) | B23: sin(ω·T) | C23: =SIN(C17*C18) -> 0.84147098
A24: cos(ωT) | B24: cos(ω·T) | C24: =COS(C17*C18) -> 0.54030231
A25: cot(ωT) | B25: cos(ωT)/sin(ωT) | C25: =COS(C17*C18)/SIN(C17*C18) -> 0.64209262
A26: |A| | B26: √(mω/2πℏ|sinωT|) | C26: =SQRT(C16*C17/(2*PI()*C19*ABS(SIN(C17*C18)))) -> 0.43490109 | E26: Prefactor magnitude
A27: θ_A | B27: −π/4 | C27: =-PI()/4 -> -0.78539816 | E27: arg of A; = −π/4 when sinωT>0
A28: φ | B28: mω·cot(ωT)/(2ℏ) | C28: =C16*C17*COS(C17*C18)/(2*C19*SIN(C17*C18)) -> 0.32104631 | E28: Exponent coefficient

Sheet Numerical Results
A1: QHO Mehler Kernel — Numerical Results (x_i=0, T=1, m=1, ω=1, ℏ=1)
A2: K(x_f) = A·exp(i·φ·x_f²) | All cells (except x_f) are Excel formulas — change parameters on Theory & Parameters sheet and this table recalculates automatically.
A3: V(x) = ½·m·ω²·x² = ½x² | Blue = input (x_f) | White = formula result | Coloured = key outputs
A4: x_f [input] | B4: Trig Functions of ωT | E4: Prefactor A | G4: Exponent Phase | I4: K (complex) | K4: Re[K] | L4: Im[K] | M4: |K| | N4: arg(K) [rad]
B5: sin(ωT) | C5: cos(ωT) | D5: cot(ωT) =cos/sin | E5: |A| =√(mω/2πℏ|sinωT|) | F5: θ_A =−π/4 [rad] | G5: φ =mω·cot/(2ℏ) | H5: φ·x_f² [rad] | I5: Total phase θ_A+φ·x_f² [rad] | J5: K complex =Re+i·Im
A6: 0 | B6: ='Theory & Parameters'!$C$23 -> 0.84147098 | C6: ='Theory & Parameters'!$C$24 -> 0.54030231 | D6: ='Theory & Parameters'!$C$25 -> 0.64209262 | E6: ='Theory & Parameters'!$C$26 -> 0.43490109 | F6: ='Theory & Parameters'!$C$27 -> -0.78539816 | G6: ='Theory & Parameters'!$C$28 -> 0.32104631 | H6: =G6*A6^2 -> 0 | I6: =F6+H6 -> -0.78539816 | J6: =TEXT(K6,"0.000000")&" + "&TEXT(L6,"0.000000")&"i" -> 0.307522 + -0.307522i | K6: =E6*COS(I6) -> 0.30752151 | L6: =E6*SIN(I6) -> -0.30752151 | M6: =SQRT(K6^2+L6^2) -> 0.43490109 | N6: =ATAN2(K6,L6) -> -0.78539816
A7: 0.25 | B7: ='Theory & Parameters'!$C$23 -> 0.84147098 | C7: ='Theory & Parameters'!$C$24 -> 0.54030231 | D7: ='Theory & Parameters'!$C$25 -> 0.64209262 | E7: ='Theory & Parameters'!$C$26 -> 0.43490109 | F7: ='Theory & Parameters'!$C$27 -> -0.78539816 | G7: ='Theory & Parameters'!$C$28 -> 0.32104631 | H7: =G7*A7^2 -> 0.020065394 | I7: =F7+H7 -> -0.76533277 | J7: =TEXT(K7,"0.000000")&" + "&TEXT(L7,"0.000000")&"i" -> 0.313630 + -0.301289i | K7: =E7*COS(I7) -> 0.31362973 | L7: =E7*SIN(I7) -> -0.30128948 | M7: =SQRT(K7^2+L7^2) -> 0.43490109 | N7: =ATAN2(K7,L7) -> -0.76533277
A8: 0.5 | B8: ='Theory & Parameters'!$C$23 -> 0.84147098 | C8: ='Theory & Parameters'!$C$24 -> 0.54030231 | D8: ='Theory & Parameters'!$C$25 -> 0.64209262 | E8: ='Theory & Parameters'!$C$26 -> 0.43490109 | F8: ='Theory & Parameters'!$C$27 -> -0.78539816 | G8: ='Theory & Parameters'!$C$28 -> 0.32104631 | H8: =G8*A8^2 -> 0.080261577 | I8: =F8+H8 -> -0.70513659 | J8: =TEXT(K8,"0.000000")&" + "&TEXT(L8,"0.000000")&"i" -> 0.331187 + -0.281876i | K8: =E8*COS(I8) -> 0.33118719 | L8: =E8*SIN(I8) -> -0.28187586 | M8: =SQRT(K8^2+L8^2) -> 0.43490109 | N8: =ATAN2(K8,L8) -> -0.70513659
A9: 0.75 | B9: ='Theory & Parameters'!$C$23 -> 0.84147098 | C9: ='Theory & Parameters'!$C$24 -> 0.54030231 | D9: ='Theory & Parameters'!$C$25 -> 0.64209262 | E9: ='Theory & Parameters'!$C$26 -> 0.43490109 | F9: ='Theory & Parameters'!$C$27 -> -0.78539816 | G9: ='Theory & Parameters'!$C$28 -> 0.32104631 | H9: =G9*A9^2 -> 0.18058855 | I9: =F9+H9 -> -0.60480962 | J9: =TEXT(K9,"0.000000")&" + "&TEXT(L9,"0.000000")&"i" -> 0.357754 + -0.247287i | K9: =E9*COS(I9) -> 0.35775414 | L9: =E9*SIN(I9) -> -0.24728714 | M9: =SQRT(K9^2+L9^2) -> 0.43490109 | N9: =ATAN2(K9,L9) -> -0.60480962
A10: 1 | B10: ='Theory & Parameters'!$C$23 -> 0.84147098 | C10: ='Theory & Parameters'!$C$24 -> 0.54030231 | D10: ='Theory & Parameters'!$C$25 -> 0.64209262 | E10: ='Theory & Parameters'!$C$26 -> 0.43490109 | F10: ='Theory & Parameters'!$C$27 -> -0.78539816 | G10: ='Theory & Parameters'!$C$28 -> 0.32104631 | H10: =G10*A10^2 -> 0.32104631 | I10: =F10+H10 -> -0.46435186 | J10: =TEXT(K10,"0.000000")&" + "&TEXT(L10,"0.000000")&"i" -> 0.388850 + -0.194768i | K10: =E10*COS(I10) -> 0.38885029 | L10: =E10*SIN(I10) -> -0.19476757 | M10: =SQRT(K10^2+L10^2) -> 0.43490109 | N10: =ATAN2(K10,L10) -> -0.46435186
A11: 1.25 | B11: ='Theory & Parameters'!$C$23 -> 0.84147098 | C11: ='Theory & Parameters'!$C$24 -> 0.54030231 | D11: ='Theory & Parameters'!$C$25 -> 0.64209262 | E11: ='Theory & Parameters'!$C$26 -> 0.43490109 | F11: ='Theory & Parameters'!$C$27 -> -0.78539816 | G11: ='Theory & Parameters'!$C$28 -> 0.32104631 | H11: =G11*A11^2 -> 0.50163486 | I11: =F11+H11 -> -0.28376331 | J11: =TEXT(K11,"0.000000")&" + "&TEXT(L11,"0.000000")&"i" -> 0.417509 + -0.121759i | K11: =E11*COS(I11) -> 0.41750879 | L11: =E11*SIN(I11) -> -0.12175944 | M11: =SQRT(K11^2+L11^2) -> 0.43490109 | N11: =ATAN2(K11,L11) -> -0.28376331
A12: 1.5 | B12: ='Theory & Parameters'!$C$23 -> 0.84147098 | C12: ='Theory & Parameters'!$C$24 -> 0.54030231 | D12: ='Theory & Parameters'!$C$25 -> 0.64209262 | E12: ='Theory & Parameters'!$C$26 -> 0.43490109 | F12: ='Theory & Parameters'!$C$27 -> -0.78539816 | G12: ='Theory & Parameters'!$C$28 -> 0.32104631 | H12: =G12*A12^2 -> 0.72235419 | I12: =F12+H12 -> -0.06304397 | J12: =TEXT(K12,"0.000000")&" + "&TEXT(L12,"0.000000")&"i" -> 0.434037 + -0.027400i | K12: =E12*COS(I12) -> 0.43403711 | L12: =E12*SIN(I12) -> -0.027399733 | M12: =SQRT(K12^2+L12^2) -> 0.43490109 | N12: =ATAN2(K12,L12) -> -0.06304397
A13: 1.75 | B13: ='Theory & Parameters'!$C$23 -> 0.84147098 | C13: ='Theory & Parameters'!$C$24 -> 0.54030231 | D13: ='Theory & Parameters'!$C$25 -> 0.64209262 | E13: ='Theory & Parameters'!$C$26 -> 0.43490109 | F13: ='Theory & Parameters'!$C$27 -> -0.78539816 | G13: ='Theory & Parameters'!$C$28 -> 0.32104631 | H13: =G13*A13^2 -> 0.98320432 | I13: =F13+H13 -> 0.19780615 | J13: =TEXT(K13,"0.000000")&" + "&TEXT(L13,"0.000000")&"i" -> 0.426421 + 0.085466i | K13: =E13*COS(I13) -> 0.42642055 | L13: =E13*SIN(I13) -> 0.085466214 | M13: =SQRT(K13^2+L13^2) -> 0.43490109 | N13: =ATAN2(K13,L13) -> 0.19780615
A14: 2 | B14: ='Theory & Parameters'!$C$23 -> 0.84147098 | C14: ='Theory & Parameters'!$C$24 -> 0.54030231 | D14: ='Theory & Parameters'!$C$25 -> 0.64209262 | E14: ='Theory & Parameters'!$C$26 -> 0.43490109 | F14: ='Theory & Parameters'!$C$27 -> -0.78539816 | G14: ='Theory & Parameters'!$C$28 -> 0.32104631 | H14: =G14*A14^2 -> 1.2841852 | I14: =F14+H14 -> 0.49878707 | J14: =TEXT(K14,"0.000000")&" + "&TEXT(L14,"0.000000")&"i" -> 0.381914 + 0.208040i | K14: =E14*COS(I14) -> 0.38191423 | L14: =E14*SIN(I14) -> 0.20803961 | M14: =SQRT(K14^2+L14^2) -> 0.43490109 | N14: =ATAN2(K14,L14) -> 0.49878707
A15: 2.25 | B15: ='Theory & Parameters'!$C$23 -> 0.84147098 | C15: ='Theory & Parameters'!$C$24 -> 0.54030231 | D15: ='Theory & Parameters'!$C$25 -> 0.64209262 | E15: ='Theory & Parameters'!$C$26 -> 0.43490109 | F15: ='Theory & Parameters'!$C$27 -> -0.78539816 | G15: ='Theory & Parameters'!$C$28 -> 0.32104631 | H15: =G15*A15^2 -> 1.6252969 | I15: =F15+H15 -> 0.83989877 | J15: =TEXT(K15,"0.000000")&" + "&TEXT(L15,"0.000000")&"i" -> 0.290313 + 0.323817i | K15: =E15*COS(I15) -> 0.29031309 | L15: =E15*SIN(I15) -> 0.32381672 | M15: =SQRT(K15^2+L15^2) -> 0.43490109 | N15: =ATAN2(K15,L15) -> 0.83989877
A16: 2.5 | B16: ='Theory & Parameters'!$C$23 -> 0.84147098 | C16: ='Theory & Parameters'!$C$24 -> 0.54030231 | D16: ='Theory & Parameters'!$C$25 -> 0.64209262 | E16: ='Theory & Parameters'!$C$26 -> 0.43490109 | F16: ='Theory & Parameters'!$C$27 -> -0.78539816 | G16: ='Theory & Parameters'!$C$28 -> 0.32104631 | H16: =G16*A16^2 -> 2.0065394 | I16: =F16+H16 -> 1.2211413 | J16: =TEXT(K16,"0.000000")&" + "&TEXT(L16,"0.000000")&"i" -> 0.148986 + 0.408586i | K16: =E16*COS(I16) -> 0.1489857 | L16: =E16*SIN(I16) -> 0.40858563 | M16: =SQRT(K16^2+L16^2) -> 0.43490109 | N16: =ATAN2(K16,L16) -> 1.2211413
A17: 2.75 | B17: ='Theory & Parameters'!$C$23 -> 0.84147098 | C17: ='Theory & Parameters'!$C$24 -> 0.54030231 | D17: ='Theory & Parameters'!$C$25 -> 0.64209262 | E17: ='Theory & Parameters'!$C$26 -> 0.43490109 | F17: ='Theory & Parameters'!$C$27 -> -0.78539816 | G17: ='Theory & Parameters'!$C$28 -> 0.32104631 | H17: =G17*A17^2 -> 2.4279127 | I17: =F17+H17 -> 1.6425145 | J17: =TEXT(K17,"0.000000")&" + "&TEXT(L17,"0.000000")&"i" -> -0.031164 + 0.433783i | K17: =E17*COS(I17) -> -0.031163598 | L17: =E17*SIN(I17) -> 0.43378311 | M17: =SQRT(K17^2+L17^2) -> 0.43490109 | N17: =ATAN2(K17,L17) -> 1.6425145
... A46: 10 | B46: ='Theory & Parameters'!$C$23 -> 0.84147098 | C46: ='Theory & Parameters'!$C$24 -> 0.54030231 | D46: ='Theory & Parameters'!$C$25 -> 0.64209262 | E46: ='Theory & Parameters'!$C$26 -> 0.43490109 | F46: ='Theory & Parameters'!$C$27 -> -0.78539816 | G46: ='Theory & Parameters'!$C$28 -> 0.32104631 | H46: =G46*A46^2 -> 32.104631 | I46: =F46+H46 -> 31.319233 | J46: =TEXT(K46,"0.000000")&" + "&TEXT(L46,"0.000000")&"i" -> 0.432870 + -0.041987i | K46: =E46*COS(I46) -> 0.43286957 | L46: =E46*SIN(I46) -> -0.041986785 | M46: =SQRT(K46^2+L46^2) -> 0.43490109 | N46: =ATAN2(K46,L46) -> -0.096693903

Sheet Worked Examples
A1: Step-by-Step Worked Examples — QHO Mehler Kernel (all formula cells reference Parameters sheet)
A2: Parameters: m=C16, ω=C17, T=C18, ℏ=C19 on 'Theory & Parameters' sheet. Change those values and all results below update automatically.
A3: x_f = 0.0
A4: Step | B4: Description | C4: Mathematical Expression | D4: Formula used | E4: Substitution (text) | F4: Result | G4: Unit/Notes
A5: 1 | B5: ωT | C5: ω × T | D5: ='Theory & Parameters'!$C$17*'Theory & Parameters'!$C$18 -> 1 | E5: ='Theory & Parameters'!$C$17*'Theory & Parameters'!$C$18 -> 1 | F5: ='Theory & Parameters'!$C$17*'Theory & Parameters'!$C$18 -> 1 | G5: rad
A6: 2 | B6: sin(ωT) | C6: sin(ω·T) | D6: =SIN('Theory & Parameters'!$C$17*'Theory & Parameters'!$C$18) -> 0.84147098 | E6: =SIN('Theory & Parameters'!$C$17*'Theory & Parameters'!$C$18) -> 0.84147098 | F6: =SIN('Theory & Parameters'!$C$17*'Theory & Parameters'!$C$18) -> 0.84147098
A7: 3 | B7: cos(ωT) | C7: cos(ω·T) | D7: =COS('Theory & Parameters'!$C$17*'Theory & Parameters'!$C$18) -> 0.54030231 | E7: =COS('Theory & Parameters'!$C$17*'Theory & Parameters'!$C$18) -> 0.54030231 | F7: =COS('Theory & Parameters'!$C$17*'Theory & Parameters'!$C$18) -> 0.54030231
A8: 4 | B8: cot(ωT) | C8: cos(ωT) / sin(ωT) | D8: =E7/E6 -> 0.64209262 | E8: =E7/E6 -> 0.64209262 | F8: =E7/E6 -> 0.64209262
A9: 5 | B9: Prefactor magnitude |A| | C9: √[ mω / (2π·ℏ·|sinωT|) ] | D9: =SQRT('Theory & Parameters'!$C$16*'Theory & Parameters'!$C$17/(2*PI()*'Theory & Parameters'!$C$19*ABS(E6))) -> 0.43490109 | E9: =SQRT('Theory & Parameters'!$C$16*'Theory & Parameters'!$C$17/(2*PI()*'Theory & Parameters'!$C$19*ABS(E6))) -> 0.43490109 | F9: =SQRT('Theory & Parameters'!$C$16*'Theory & Parameters'!$C$17/(2*PI()*'Theory & Parameters'!$C$19*ABS(E6))) -> 0.43490109 | G9: const in x_f
A10: 6 | B10: Prefactor phase θ_A | C10: arg(√(1/i)) = −π/4 | D10: =-PI()/4 -> -0.78539816 | E10: =-PI()/4 -> -0.78539816 | F10: =-PI()/4 -> -0.78539816 | G10: rad; always −π/4 when sinωT>0
A11: 7 | B11: Phase coefficient φ | C11: mω·cot(ωT) / (2·ℏ) | D11: ='Theory & Parameters'!$C$16*'Theory & Parameters'!$C$17*E8/(2*'Theory & Parameters'!$C$19) -> 0.32104631 | E11: ='Theory & Parameters'!$C$16*'Theory & Parameters'!$C$17*E8/(2*'Theory & Parameters'!$C$19) -> 0.32104631 | F11: ='Theory & Parameters'!$C$16*'Theory & Parameters'!$C$17*E8/(2*'Theory & Parameters'!$C$19) -> 0.32104631 | G11: rad/length²
A12: 8 | B12: φ·x_f² (x_f=0.0) | C12: φ × x_f² | D12: =E11*0^2 -> 0 | E12: =E11*0^2 -> 0 | F12: =E11*0^2 -> 0 | G12: rad (pure-imag exponent)
A13: 9 | B13: Total phase of K | C13: θ_A + φ·x_f² | D13: =E10+E12 -> -0.78539816 | E13: =E10+E12 -> -0.78539816 | F13: =E10+E12 -> -0.78539816 | G13: rad
A14: 10 | B14: Re[K] = |A|·cos(total phase) | C14: |A| · cos(θ_A + φ·x_f²) | D14: =E9*COS(E13) -> 0.30752151 | E14: =E9*COS(E13) -> 0.30752151 | F14: =E9*COS(E13) -> 0.30752151
A15: 11 | B15: Im[K] = |A|·sin(total phase) | C15: |A| · sin(θ_A + φ·x_f²) | D15: =E9*SIN(E13) -> -0.30752151 | E15: =E9*SIN(E13) -> -0.30752151 | F15: =E9*SIN(E13) -> -0.30752151
A16: 12 | B16: |K| (modulus) | C16: √( Re[K]² + Im[K]² ) | D16: =SQRT(E14^2+E15^2) -> 0.43490109 | E16: =SQRT(E14^2+E15^2) -> 0.43490109 | F16: =SQRT(E14^2+E15^2) -> 0.43490109 | G16: equals |A| always
A17: 13 | B17: arg(K) [rad] | C17: atan2( Im[K], Re[K] ) | D17: =ATAN2(E14,E15) -> -0.78539816 | E17: =ATAN2(E14,E15) -> -0.78539816 | F17: =ATAN2(E14,E15) -> -0.78539816 | G17: rad; equals total phase
A18: ⇒ | B18: Final propagator value K | C18: Re[K] + i · Im[K] | D18: =TEXT(E14,"0.000000")&" + "&TEXT(E15,"0.000000")&"·i" -> 0.307522 + -0.307522·i | E18: =TEXT(E14,"0.000000")&" + "&TEXT(E15,"0.000000")&"·i" -> 0.307522 + -0.307522·i | F18: =TEXT(E14,"0.000000")&" + "&TEXT(E15,"0.000000")&"·i" -> 0.307522 + -0.307522·i | G18: complex number
A21: x_f = 2.5
A22: Step | B22: Description | C22: Mathematical Expression | D22: Formula used | E22: Substitution (text) | F22: Result | G22: Unit/Notes
A23: 1 | B23: ωT | C23: ω × T | D23: ='Theory & Parameters'!$C$17*'Theory & Parameters'!$C$18 -> 1 | E23: ='Theory & Parameters'!$C$17*'Theory & Parameters'!$C$18 -> 1 | F23: ='Theory & Parameters'!$C$17*'Theory & Parameters'!$C$18 -> 1 | G23: rad
A24: 2 | B24: sin(ωT) | C24: sin(ω·T) | D24: =SIN('Theory & Parameters'!$C$17*'Theory & Parameters'!$C$18) -> 0.84147098 | E24: =SIN('Theory & Parameters'!$C$17*'Theory & Parameters'!$C$18) -> 0.84147098 | F24: =SIN('Theory & Parameters'!$C$17*'Theory & Parameters'!$C$18) -> 0.84147098
A25: 3 | B25: cos(ωT) | C25: cos(ω·T) | D25: =COS('Theory & Parameters'!$C$17*'Theory & Parameters'!$C$18) -> 0.54030231 | E25: =COS('Theory & Parameters'!$C$17*'Theory & Parameters'!$C$18) -> 0.54030231 | F25: =COS('Theory & Parameters'!$C$17*'Theory & Parameters'!$C$18) -> 0.54030231
A26: 4 | B26: cot(ωT) | C26: cos(ωT) / sin(ωT) | D26: =E25/E24 -> 0.64209262 | E26: =E25/E24 -> 0.64209262 | F26: =E25/E24 -> 0.64209262
A27: 5 | B27: Prefactor magnitude |A| | C27: √[ mω / (2π·ℏ·|sinωT|) ] | D27: =SQRT('Theory & Parameters'!$C$16*'Theory & Parameters'!$C$17/(2*PI()*'Theory & Parameters'!$C$19*ABS(E24))) -> 0.43490109 | E27: =SQRT('Theory & Parameters'!$C$16*'Theory & Parameters'!$C$17/(2*PI()*'Theory & Parameters'!$C$19*ABS(E24))) -> 0.43490109 | F27: =SQRT('Theory & Parameters'!$C$16*'Theory & Parameters'!$C$17/(2*PI()*'Theory & Parameters'!$C$19*ABS(E24))) -> 0.43490109 | G27: const in x_f
A28: 6 | B28: Prefactor phase θ_A | C28: arg(√(1/i)) = −π/4 | D28: =-PI()/4 -> -0.78539816 | E28: =-PI()/4 -> -0.78539816 | F28: =-PI()/4 -> -0.78539816 | G28: rad; always −π/4 when sinωT>0
A29: 7 | B29: Phase coefficient φ | C29: mω·cot(ωT) / (2·ℏ) | D29: ='Theory & Parameters'!$C$16*'Theory & Parameters'!$C$17*E26/(2*'Theory & Parameters'!$C$19) -> 0.32104631 | E29: ='Theory & Parameters'!$C$16*'Theory & Parameters'!$C$17*E26/(2*'Theory & Parameters'!$C$19) -> 0.32104631 | F29: ='Theory & Parameters'!$C$16*'Theory & Parameters'!$C$17*E26/(2*'Theory & Parameters'!$C$19) -> 0.32104631 | G29: rad/length²
A30: 8 | B30: φ·x_f² (x_f=2.5) | C30: φ × x_f² | D30: =E29*2.5^2 -> 2.0065394 | E30: =E29*2.5^2 -> 2.0065394 | F30: =E29*2.5^2 -> 2.0065394 | G30: rad (pure-imag exponent)
A31: 9 | B31: Total phase of K | C31: θ_A + φ·x_f² | D31: =E28+E30 -> 1.2211413 | E31: =E28+E30 -> 1.2211413 | F31: =E28+E30 -> 1.2211413 | G31: rad
A32: 10 | B32: Re[K] = |A|·cos(total phase) | C32: |A| · cos(θ_A + φ·x_f²) | D32: =E27*COS(E31) -> 0.1489857 | E32: =E27*COS(E31) -> 0.1489857 | F32: =E27*COS(E31) -> 0.1489857
A33: 11 | B33: Im[K] = |A|·sin(total phase) | C33: |A| · sin(θ_A + φ·x_f²) | D33: =E27*SIN(E31) -> 0.40858563 | E33: =E27*SIN(E31) -> 0.40858563 | F33: =E27*SIN(E31) -> 0.40858563
A34: 12 | B34: |K| (modulus) | C34: √( Re[K]² + Im[K]² ) | D34: =SQRT(E32^2+E33^2) -> 0.43490109 | E34: =SQRT(E32^2+E33^2) -> 0.43490109 | F34: =SQRT(E32^2+E33^2) -> 0.43490109 | G34: equals |A| always
A35: 13 | B35: arg(K) [rad] | C35: atan2( Im[K], Re[K] ) | D35: =ATAN2(E32,E33) -> 1.2211413 | E35: =ATAN2(E32,E33) -> 1.2211413 | F35: =ATAN2(E32,E33) -> 1.2211413 | G35: rad; equals total phase
A36: ⇒ | B36: Final propagator value K | C36: Re[K] + i · Im[K] | D36: =TEXT(E32,"0.000000")&" + "&TEXT(E33,"0.000000")&"·i" -> 0.148986 + 0.408586·i | E36: =TEXT(E32,"0.000000")&" + "&TEXT(E33,"0.000000")&"·i" -> 0.148986 + 0.408586·i | F36: =TEXT(E32,"0.000000")&" + "&TEXT(E33,"0.000000")&"·i" -> 0.148986 + 0.408586·i | G36: complex number
A39: x_f = 5.0
A40: Step | B40: Description | C40: Mathematical Expression | D40: Formula used | E40: Substitution (text) | F40: Result | G40: Unit/Notes
A41: 1 | B41: ωT | C41: ω × T | D41: ='Theory & Parameters'!$C$17*'Theory & Parameters'!$C$18 -> 1 | E41: ='Theory & Parameters'!$C$17*'Theory & Parameters'!$C$18 -> 1 | F41: ='Theory & Parameters'!$C$17*'Theory & Parameters'!$C$18 -> 1 | G41: rad
A42: 2 | B42: sin(ωT) | C42: sin(ω·T) | D42: =SIN('Theory & Parameters'!$C$17*'Theory & Parameters'!$C$18) -> 0.84147098 | E42: =SIN('Theory & Parameters'!$C$17*'Theory & Parameters'!$C$18) -> 0.84147098 | F42: =SIN('Theory & Parameters'!$C$17*'Theory & Parameters'!$C$18) -> 0.84147098
A43: 3 | B43: cos(ωT) | C43: cos(ω·T) | D43: =COS('Theory & Parameters'!$C$17*'Theory & Parameters'!$C$18) -> 0.54030231 | E43: =COS('Theory & Parameters'!$C$17*'Theory & Parameters'!$C$18) -> 0.54030231 | F43: =COS('Theory & Parameters'!$C$17*'Theory & Parameters'!$C$18) -> 0.54030231
A44: 4 | B44: cot(ωT) | C44: cos(ωT) / sin(ωT) | D44: =E43/E42 -> 0.64209262 | E44: =E43/E42 -> 0.64209262 | F44: =E43/E42 -> 0.64209262
...
